Workbook

Sheet STARTUPS
A1: No. | B1: Year | C1: Resolution No: | D1: TYPE | E1: Program | F1: Project Title | G1: Name of Proponent | H1: Contact Details | I1: Amount | J1: CLASS | K1: STATUS | L1: Promotional Assistance | M1: Revenue Growth (annual/cumulative) | N1: Jobs Created | O1: Investments Attracted (private co-investment, seed, VC, grants) | P1: Market Reach (local, regional, global) | Q1: High-tech Exports (export volume/value) if applicable | R1: Social Impact | S1: Next Possible Intervention
A2: 1 | B2: 2018 | C2: NA | D2: PAC | E2: TECHNICOM 1.0 | F2: Optimization of an Industry Grade Prototype of Po Lite Products | G2: Dr. Ria Liza Canlas | H2: riadear21@yahoo.com | I2: 4999045 | J2: STARTUP
A3: 2 | B3: 2018 | C3: NA | D3: PAC | E3: TECHNICOM 1.0 | F3: Pilot Testing of a Deepwater Operation 3D Visual Mapping and Inspection System (PD-DOMAINS) | G3: Mr. Francis James Corpuz ANTIPARA Exploration Inc. | H3: franciscorpuz@gmail.com | I3: 3058155.2 | J3: STARTUP
A4: 3 | B4: 2018 | C4: NA | D4: PAC | E4: TECHNICOM 1.0 | F4: Development of an Alternative Credit Scoring Model applying Machine Learning in Financing Farmers | G4: Mr. Ruel T. Amparo Cropital Enterprises Corporation | H4: ruel@cropital.com | I4: 3551018 | J4: STARTUP
A5: 4 | B5: 2019 | C5: NA | D5: PAC | E5: TECHNICOM 1.0 | F5: Product Design, Manufacturing and Field Scale Testing of StillFresh: Spoilage Monitoring Strip | G5: Mr. Joseph Christopher G. Doroja | H5: joseph.doroja@obf.ateneo.edu, etinhay@gmail.com | I5: 1636971 | J5: STARTUP
A6: 5 | B6: 2019 | C6: NA | D6: PAC | E6: TECHNICOM 1.0 | F6: Integration of Data Science and Scaling Up of Payruler, a comprehensive Human Resource Management System (HRMS) | G6: Mr. Warlito Pio S. De Jesus | H6: jojo@geniihut.com, jojo@payruler.com, timmy@geniihut.com, timmy@payruler.com | I6: 3258768 | J6: STARTUP
A7: 6 | B7: 2019 | C7: NA | D7: PAC | E7: TECHNICOM 1.0 | F7: Optimization of Virtual Reality Kit (VR Kit) for New Media Technology and Commercial Competitiveness | G7: Mr. Ryan Tan Yu | H7: ryan@mataverse.ph | I7: 4019382 | J7: STARTUP
A8: 7 | B8: 2019 | C8: NA | D8: PAC | E8: TECHNICOM 1.0 | F8: Enhancement of the Micab Cab Hailing Engine thru Big Data Analytics | G8: CONRADO D. CAMILON JR, Project Leader ALEXA’S ENGINEERING SERVICES | I8: 3135851.2 | J8: STARTUP
A9: 8 | B9: 2019 | C9: NA | D9: PAC | E9: TECHNICOM 1.0 | F9: Scale-up Manufacturing of Biotek-M Diagnostic Kits and Post Marketing for Third Party Evaluation | G9: Dr. Raul V. Destura Denise Lacuna | H9: rvdestura@up.edu.ph jadelacuna12@gmail.com | I9: 16926594 | J9: STARTUP
A10: 9 | B10: 2019 | C10: NA | D10: PAC | E10: TECHNICOM 1.0 | F10: Technology Enhancement and Commercialization of Exora Intellex as an Energy Analytics Machine Learning Platform for Industrial Smart Energy Management and Electricity Cost Reduction | G10: Mr. Sergius Angelo Santos Exora Technologies, Inc. | H10: sergius@exora.ph | I10: 4394800 | J10: STARTUP
A11: 10 | B11: 2019 | C11: 2019-54 | D11: APPROVAL | E11: VFP | F11: Application for Local and International Certifications of Manila Healthtek, Inc. as a Manufacturing Company for Molecular-Based Diagnostic kits | G11: Dr. Raul V. Destura President/CEO Manila Healthtek , Inc. | H11: rvdestura@up.edu.ph | I11: 3792164.9 | J11: STARTUP | K11: COMPLETED
A12: 11 | B12: 2020 | C12: 2020-07-memo | D12: APPROVAL | E12: IBED | F12: Pilot Production of " Snap On and Off Handle for a Five-Gallon Bottle Container" | G12: Mr. Carlos N. Detalo Jr. | H12: - | I12: 409314 | J12: STARTUP
A13: 12 | B13: 2021 | C13: 2021-46 | D13: APPROVAL | E13: IBED | F13: PIlot Scale Production of Cooked Balut in Shell with Commercially Acceptable Shelf-life for Feasibility and Marketing Testing | G13: Ambrocio Kerwin A. Perez | H13: - | I13: 349800 | J13: STARTUP
A14: 13 | B14: 2022 | C14: 2022-109 | D14: APPROVAL | E14: ITECH | F14: Commercialization of Maker-scope | G14: MR. JEREMY C. DE LEON | I14: 1083679 | J14: STARTUP | K14: WIDTHRAWN
A15: 14 | B15: 2022 | C15: 2022-109 | D15: PROMOTION | E15: ITECH | F15: Commercialization of Maker-scope | G15: MR. JEREMY C. DE LEON | H15: jeremycdeleon@gmail.com | I15: 1083679 | J15: STARTUP | K15: COMPLETED | L15: Marketing Assistance Program, SIIF
A16: 15 | B16: 2023 | C16: NA | D16: PROMOTION | E16: GALING | F16: Technology Validation of Pili Seal | G16: Engr. Mark Kennedy E. Bantugon | H16: markkennedy09bantugon@gmail.com | I16: 349799.56 | J16: STARTUP | K16: ONGOING | L16: Marketing Assistance Program, LUNDUYAN
A17: 16 | B17: 2023 | C17: NA | D17: PROMOTION | E17: GALING | F17: Improved KoolGear | G17: Mr. Ivan Brent Nara | H17: naraivanbrent@gmail.com | I17: 96107 | J17: STARTUP | L17: Marketing Assistance Program
A18: 17 | B18: 2023 | C18: NA | D18: PROMOTION | E18: GALING | F18: Foldable Water Tank with Zeramic Filter | G18: Ms. Eleanor M. Olegario | H18: lithos.opc.2021@gmail.com | I18: 191500 | J18: STARTUP | L18: Marketing Assistance Program, LUNDUYAN
A19: 18 | B19: 2025 | C19: 2025-17 | D19: APPROVAL | E19: GALING | F19: Fabrication, and Installation of a 50W LED Flood Light Post with Integration of Small-scale Savonius-Type Helical Vertical Axis Wind Turbine (VAWT) and Solar Panel | G19: Engr. Jose Luis L. Villalon | H19: louie.vdaliinnovations@gmail.com +63 915 126 5571 | I19: 358538 | J19: STARTUP | K19: ONGOING
A20: 19 | B20: 2025 | C20: NA | E20: EIPRAP | F20: Enhancement, Market Validation and Pilot Production of AI-Driven Farm Management Module (AID-FMM) | G20: Waste4good Research and Experimental Development in Engineering and Technology | H20: lurelynpablo@gmail.com lorilyn.daquioag@eee.upd.edu.ph 639385504997 | J20: STARTUP | K20: ONGOING
A21: 20 | B21: 2025 | C21: NA | E21: EIPRAP | F21: High-resolution 3D Geological Mapping with Ambient Electromagnetic Interferometry | G21: Emmanuel G. Ramos Mark Linus C. Ramos Rodolfo Alfonso R. Sabio | H21: - | J21: STARTUP | K21: ONGOING
A22: 21 | B22: 2025 | C22: NA | E22: EIPRAP | F22: A System and Method for Managing Healthcare Services and Networks | G22: SeeYouDoc Corporation | H22: noel@seeyoudoc.com | J22: STARTUP | K22: ONGOING
A23: 22 | B23: 2025 | C23: NA | D23: ISIPAG | E23: IPRAP | F23: A System and Method for Managing Healthcare Services and Networks (NPE - South Korea) | G23: SeeYouDoc Corporation | H23: noel@seeyoudoc.com | J23: STARTUP | K23: ONGOING
A24: 23 | B24: 2025 | C24: NA | D24: ISIPAG | E24: IPRAP | F24: System and Method for Secure Disbursement of Loans and Income-Based Advances with Biometric Consent and Configurable Repayment Orchestration | G24: Vashcorp Inc. | H24: varianchu@gmail.com | J24: STARTUP
A25: 24 | B25: 2025 | C25: NA | D25: ISIPAG | E25: IPRAP | F25: The Process Of Making An AI-Driven Farm Management Module And Agricultural Monitoring System (NPE - Japan) | G25: Waste4Good Technologies a.k.a. GreenVisionsPh | H25: mari@rezbin.ph, hello@rezbin.ph 639178920234 | J25: STARTUP | K25: ONGOING
A26: 25 | B26: 2025 | C26: NA | D26: PROMOTION | E26: EIPRAP | F26: Enhancement, Market Validation and Pilot Production of AI-Driven Farm Management Module (AID-FMM) | G26: Waste4good Research and Experimental Development in Engineering and Technology | H26: lurelynpablo@gmail.com lorilyn.daquioag@eee.upd.edu.ph 639385504997 | I26: 2384720 | J26: STARTUP | K26: ONGOING | L26: Market Intelligence under IMPAKT
A27: 26 | B27: 2025 | C27: NA | D27: PROMOTION | E27: EIPRAP | F27: A System and Method for Managing Healthcare Services and Networks | G27: SeeYouDoc Corporation | H27: noel@seeyoudoc.com | I27: 2332760.9 | J27: STARTUP | K27: ONGOING | L27: IEIG 2025, PHILIPPiNEXT
A28: 27 | B28: 2025 | C28: NA | D28: PROMOTION | E28: GALING | F28: Fabrication, and Installation of a 50W LED Flood Light Post with Integration of Small-scale Savonius-Type Helical Vertical Axis Wind Turbine (VAWT) and Solar Panel | G28: Engr. Jose Luis L. Villalon | H28: louie.vdaliinnovations@gmail.com +63 915 126 5571 | I28: 358538 | J28: STARTUP | K28: ONGOING
A29: 28 | B29: 2022 | C29: NA | D29: PAC | E29: TECHNICOM | F29: Commercialization of the 4Gives System | G29: Mr. Varian Sherwin Chu Vashcorp, Inc. | H29: varianchu@gmail.com | I29: 5867730.2 | J29: STARTUP | K29: ONGOING
A30: 29 | B30: 2023 | C30: 2023-79 | D30: APPROVAL | E30: GALING | F30: Improved KoolGear | G30: Mr. Ivan Brent Nara Bldg. 23, UP Bliss, Diliman, Quezon City | H30: naraivanbrent@gmail 09751905598 | I30: 96107 | J30: STARTUP | K30: ONGOING
A31: 30 | B31: 2023 | C31: 2023-66 | D31: APPROVAL | E31: GALING | F31: Foldable Water Tank with Zeramic Filter | G31: Ms. Eleanor M. Olegario | H31: eleanor.olegario@gmail.com 09209129187 | I31: 191500 | J31: STARTUP | K31: COMPLETED
A32: 31 | B32: 2023 | C32: 2023-30 | D32: APPROVAL | E32: GALING | F32: Technology Validation of Pili Seal | G32: Engr. Mark Kennedy E. Bantugon | H32: markkennedy09bantugon@gmail.com andpili.adheseal@gmail.com | I32: 349799.56 | J32: STARTUP | K32: ONGOING
A33: 32 | B33: 2023 | C33: 2023-81 | D33: APPROVAL | E33: TECHNICOM | F33: Technology and business validation of an advanced web and mobile Point-of-Sale (POS) software-as-a-service (SAAS) application for Philippine micro and small retail businesses | G33: Renzo Navarro Ducusin Project Leader IOL, Inc. | H33: kevin@iolph.com 074-6209538 | I33: 2715682.8 | J33: STARTUP | K33: ONGOING
A34: 33 | B34: 2023 | C34: 2023-83 | D34: APPROVAL | E34: TECHNICOM | F34: Determining the Pesticide Residue Level of Mangoes using a smart metal oxide nanosensor for Post-Harvest Applications | G34: Ms. Normie Jean Sajor Lacubtan Project Leader | H34: njsajor@gmail.com f.normiejean.lacubtan@cmu.edu.ph | I34: 2398683 | J34: STARTUP | K34: ONGOING
A35: 34 | B35: 2023 | C35: PAC | D35: APPROVAL | E35: TECHNICOM | F35: Scaling Digital Clustering Solution for Enhanced Agri-Value Chain Integration of Farm Konek | G35: John Vincent Q. Gastanes Project Zacchaeus Marketing Cooperative | H35: gastanesjohnvincent@gmail.com 639177979073 | I35: 7936800 | J35: STARTUP | K35: ONGOING
A36: 35 | B36: 2023 | C36: NA | D36: PROMOTION | E36: GALING | F36: Improved KoolGear | G36: Mr. Ivan Brent Nara Bldg. 23, UP Bliss, Diliman, Quezon City | H36: naraivanbrent@gmail 09751905598 | I36: 96107 | J36: STARTUP | K36: ONGOING | L36: LUNDUYAN, Marketing Assistance Program
A37: 36 | B37: 2023 | C37: NA | D37: PROMOTION | E37: GALING | F37: Foldable Water Tank with Zeramic Filter | G37: Ms. Eleanor M. Olegario | H37: eleanor.olegario@gmail.com 09209129187 | I37: 191500 | J37: STARTUP | K37: COMPLETED | L37: Marketing Assistance Program, KIWIE
A38: 37 | B38: 2023 | C38: NA | D38: PROMOTION | E38: GALING | F38: Technology Validation of Pili Seal | G38: Engr. Mark Kennedy E. Bantugon | H38: markkennedy09bantugon@gmail.com andpili.adheseal@gmail.com | I38: 349799.56 | J38: STARTUP | K38: ONGOING | L38: PHILIPPiNEXT, Marketing Assistance Program, CES 2025, SIIF
A39: 38 | B39: 2023 | C39: NA | D39: PROMOTION | E39: TECHNICOM | F39: Technology and business validation of an advanced web and mobile Point-of-Sale (POS) software-as-a-service (SAAS) application for Philippine micro and small retail businesses | G39: Renzo Navarro Ducusin Project Leader IOL, Inc. | H39: kevin@iolph.com 074-6209538 | I39: 2715682.8 | J39: STARTUP | K39: ONGOING
A40: 39 | B40: 2023 | C40: NA | D40: PROMOTION | E40: TECHNICOM | F40: Determining the Pesticide Residue Level of Mangoes using a smart metal oxide nanosensor for Post-Harvest Applications | G40: Ms. Normie Jean Sajor Lacubtan Project Leader | H40: njsajor@gmail.com f.normiejean.lacubtan@cmu.edu.ph | I40: 2398683 | J40: STARTUP | K40: ONGOING
...

Sheet Copy of IDD_STARTUPS
A1: Year | B1: Resolution No: | C1: TYPE | D1: Program | E1: Approval Date | F1: Project Title | G1: Name of Proponent | H1: Address | I1: Contact Details | J1: Amount | K1: CLASS | L1: STATUS | M1: POSSIBLE FOLLOW UP ASSITANCE
A2: 2025 | B2: 2025-18 | C2: APPROVAL | D2: GALING | E2: 2025 | F2: Magicbag: Wireless slow cooker | G2: Ms. Rowena Faith Armeniana Sucalit 4423 Montojo St. Tejeros, Makati City | I2: weng747@yahoo.com 0916-777-8031 | J2: 229654 | K2: STARTUP | L2: ONGOING
A3: 2024 | B3: 2024-89 | C3: APPROVAL | D3: GALING | E3: 45625 | F3: Marissa Turbine: Vertical-Axis Tidal Turbine | G3: Mr. Patrick Roland de Guzman 65 Lawa, Obando, Bulacan | I3: deguzmanpatrickroland@gmail.com 09974916634 | J3: 395212 | K3: STARTUP | L3: ONGOING
A4: 2024 | B4: 2024-36 | C4: APPROVAL | D4: GALING | E4: 45469 | F4: Technology Validation of Unas Canvas (UnVas) | G4: Julienne Fabie-Agapin Lumbia District, Pagadian City | I4: juliennestephanie.agapin@wmsu.edu.ph 09362660139 | J4: 43250 | K4: STARTUP | L4: COMPLETED | M4: Endorsed to NDC
A5: 2024 | B5: 2024-54 | C5: APPROVAL | D5: GALING | E5: 45544 | F5: Technology Validation of IOT Artificial Intelligence-Based Dosing System in Greenhouse | G5: Mr. Alvin Phoebe Artemis A. Valdez Interior Fidelidad Street, Barangay 1, Balayan, Batagas 4213 | I5: alvinphoebeartemis@gmail.com +639918781878; +639916453232 | J5: 236341.77 | K5: STARTUP | L5: ONGOING | M5: Endorsed to NDC
A6: 2023 | B6: 2023-79 | C6: APPROVAL | D6: GALING | E6: 45225 | F6: Improved KoolGear | G6: Mr. Ivan Brent Nara Bldg. 23, UP Bliss, Diliman, Quezon City | I6: naraivanbrent@gmail 09751905598 | J6: 96107 | K6: STARTUP | L6: ONGOING
A7: 2023 | B7: 2023-66 | C7: APPROVAL | D7: GALING | E7: 45154 | F7: Foldable Water Tank with Zeramic Filter | G7: Ms. Eleanor M. Olegario | H7: 17 Cavite Street, Bonifacio Village, Brgy. Pasong Tamo, Quezon City | I7: eleanor.olegario@gmail.com 09209129187 | J7: 191500 | K7: STARTUP | L7: COMPLETED
A8: 2023 | B8: 2023-30 | C8: APPROVAL | D8: GALING | E8: 45086 | F8: Technology Validation of Pili Seal | G8: Engr. Mark Kennedy E. Bantugon | I8: markkennedy09bantugon@gmail.com andpili.adheseal@gmail.com | J8: 349799.56 | K8: STARTUP | L8: ONGOING
A9: 2025 | B9: 2025-17 | C9: APPROVAL | D9: GALING | F9: Fabrication, and Installation of a 50W LED Flood Light Post with Integration of Small-scale Savonius-Type Helical Vertical Axis Wind Turbine (VAWT) and Solar Panel | G9: Engr. Jose Luis L. Villalon | H9: 25 Mercury, Zytek-Riosa, Brgy. Pasong Tamo, Quezon City, 1107 | I9: louie.vdaliinnovations@gmail.com +63 915 126 5571 | J9: 358538 | K9: STARTUP | L9: ONGOING
A10: 2025 | B10: NA | C10: PAC | D10: TECHNICOM | E10: 2025 | F10: Commercialization and Scaling of Duon’s Real-Time Indoor Navigation with Foot Traffic Behavioral Analysis and Prediction AI | G10: MR. GABRIEL ANTON D. ANGELES, Project Leader DUON TECHNOLOGIES INCORPORATED | H10: 7F, Panorama Tower 34th Street, corner Lane A, Taguig, 1634 Metro Manila | I10: gda4993@gmail.com, admin@duon.ph 9773470628 | J10: 7175464 | K10: STARTUP | L10: ONGOING
A11: 2025 | B11: NA | C11: PAC | D11: TECHNICOM | E11: 2025 | F11: COMMERCIAL PROTOTYPING OF SMART WATER (IOT) METER (SWIM) | G11: CONRADO D. CAMILON JR, Project Leader ALEXA’S ENGINEERING SERVICES | I11: cdcamilonjr@gmail.com 09224074861/049-501-4583 | J11: 4998689 | K11: STARTUP | L11: ONGOING
A12: 2025 | B12: NA | C12: PAC | D12: TECHNICOM | E12: 2025 | F12: Rezbin: Business Model Validation and Market Acceptability Testing for Low Cost AI-powered Bins as an Alternative to Expensive Reverse Vending Machines in Metro Manila | G12: Matthew Cristi C. Martirez, Project Leader Rezbin Waste Technology Inc. | I12: mari@rezbin.ph, hello@rezbin.ph 639178920234 | J12: 4999988 | K12: STARTUP | L12: ONGOING | M12: For endorsement to NDC
A13: 2025 | B13: NA | C13: PAC | D13: TECHNICOM | E13: 2025 | F13: Technological Improvement and Field Testing of Bamboo-based Biodegradable Period Care | G13: Alexandra B. Jocom, Project Leader BioTerra Corp. (Halia) | I13: alexa@halia.co 639764896618 | J13: 5000000 | K13: STARTUP | L13: ONGOING
A14: 2025 | B14: NA | C14: PAC | D14: TECHNICOM | E14: 2025 | F14: Scaling Up and Deployment of the Multi-Drum Chamber Carbonization System for Sustainable Charcoal Production in the Philippines | G14: Julieane M. Fernandez, Project Leader Eco-Uling by Project Lily Inc. | I14: ayafernandez.ecouling@gmail.com 0915-795-1534 | J14: 4884739 | K14: STARTUP | L14: ONGOING
A15: 2025 | B15: NA | C15: PAC | D15: TECHNICOM | E15: 2025 | F15: Optimizing Bamboo Processing: 2-IN-1 Furnace For Pole Treatment and Valorization of Silica-Rich Bamboo Ash | G15: Anneth Rigon BAMBOO IMPACT LAB OPC | I15: anneth@bambooimpactlab.com 0919-999-0488 | J15: 4993468 | K15: STARTUP | L15: ONGOING
A16: 2024 | B16: 2024-71 | C16: APPROVAL | D16: TECHNICOM | E16: 45574 | F16: Automated Coconut Sap Extraction: Enhancing Productivity and Quality Through Innovative Technology | G16: Luzmar M. Gabor KASAKA Agriventures, Inc. | I16: asaka@aim.edu 9175305742 | J16: 2998072 | K16: STARTUP | L16: ONGOING | M16: Endorsed to NDC
A17: 2024 | B17: 2024-78 | C17: APPROVAL | D17: TECHNICOM | E17: 45581 | F17: Enhancement and Market Validation of AI-Powered Property Management Solutions for the Philippines | G17: Mr. Jesehl Charles Basco Project Leader Collo/Proprty Technology Solutions Inc. | I17: jay@collo.ph 9178327166 | J17: 2911170 | K17: STARTUP | L17: ONGOING
A18: 2024 | B18: 2024-82 | C18: APPROVAL | D18: TECHNICOM | E18: 45601 | F18: Enhancement, Market Validation, and Pilot Production of AI-Driven Farm Management Module (AID-FMM) | G18: Ms. Lorilyn P. Daquioag Project leader Waste4Good technologies | I18: lurelynpablo@gmail.com lorilyn.daquioag@eee.upd.edu.ph 639385504997 | J18: 2384720 | K18: STARTUP | L18: ONGOING
A19: 2024 | B19: 2024-88 | C19: APPROVAL | D19: TECHNiCOM | E19: 45609 | F19: Improvement and Pilot Testing of Alerto PH AI-as-a-Service (AlaaS) | G19: Ms. Cristina Macaraig WiredField Philippines Inc. | I19: cristina@wiredfield.com | J19: 2975715 | K19: STARTUP | L19: ONGOING
A20: 2024 | B20: 2024-74 | C20: APPROVAL | D20: TECHNICOM | E20: 45574 | F20: Market Testing of Online Residential Rental Marketplace for Filipino Students and Young Professionals | G20: Alyssa Casandra Wee Project Leader/ Krelio Technologies Inc. | I20: alyssa@dormy.ph, hello@dormy.ph 0992 681 6544 | J20: 2999945.7 | K20: STARTUP | L20: ONGOING
A21: 2024 | B21: 2024-27 | C21: APPROVAL | D21: TECHNICOM | E21: 45441 | F21: Pilot Testing and Technology Validation of Fortified Powdered Coconut Milk as a Powdered Dairy Alternative to Lactose Intolerant and Nutrient Deficient Filipino Children and Adults | G21: Samuel Antonius De Chavez Tecuala Dehusk | H21: Martel Bldg. Verdon Parc, Unit 716 Ecoland Drive, Talomo, Bucana, Davao Del Sur, Davao City, 8000 | I21: samuel.tecuala@dehusk.com.ph 09565734432 | J21: 2789556 | K21: STARTUP | L21: ONGOING
A22: 2024 | B22: 2024-31 | C22: APPROVAL | D22: TECHNICOM | E22: 45448 | F22: Scaling up Testing of a Peer-to-Peer Car Sharing Marketplace for the Filipino Car Sharing Economy | G22: Mr. Miguel Locsin Project Leader DOON Transport Technologies Inc. | H22: Unit 302, 5048 P. Burgos Street, Draper Startup House for Entrepreneurs, Brgy. Poblacion, Makati City, Fourth District, NCR 1210 / | I22: miguel@doon.ph 09178076499 | J22: 2896644 | K22: STARTUP | L22: ONGOING
A23: 2024 | B23: 2024-26 | C23: APPROVAL | D23: TECHNICOM | E23: 45441 | F23: The Scrapcycle PH field and Market Testing of Scrap Trading Dynamics Across Philippine Urban Landscapes | G23: Genevieve P. Navales/Female Project Leader, ScrapCycle PH | I23: vievenavales29@gmail.com 09952033203 | J23: 2785599 | K23: STARTUP | L23: ONGOING
A24: 2023 | B24: 2023-81 | C24: APPROVAL | D24: TECHNICOM | E24: 45225 | F24: Technology and business validation of an advanced web and mobile Point-of-Sale (POS) software-as-a-service (SAAS) application for Philippine micro and small retail businesses | G24: Renzo Navarro Ducusin Project Leader IOL, Inc. | H24: Rm 404 Jose Miguel Bldg. Yandoc St., Baguio City. Philippines | I24: kevin@iolph.com 074-6209538 | J24: 2715682.8 | K24: STARTUP | L24: ONGOING
A25: 2023 | B25: 2023-83 | C25: APPROVAL | D25: TECHNICOM | E25: 45236 | F25: Determining the Pesticide Residue Level of Mangoes using a smart metal oxide nanosensor for Post-Harvest Applications | G25: Ms. Normie Jean Sajor Lacubtan Project Leader | I25: njsajor@gmail.com f.normiejean.lacubtan@cmu.edu.ph | J25: 2398683 | K25: STARTUP | L25: ONGOING
A26: 2023 | B26: PAC | C26: APPROVAL | D26: TECHNICOM | E26: 45275 | F26: Scaling Digital Clustering Solution for Enhanced Agri-Value Chain Integration of Farm Konek | G26: John Vincent Q. Gastanes Project Zacchaeus Marketing Cooperative | H26: Unit 1, CCT Building, Puerto Princesa City, Palawan, 5300/ MIMAROPA | I26: gastanesjohnvincent@gmail.com 639177979073 | J26: 7936800 | K26: STARTUP | L26: ONGOING
A27: 2022 | C27: PAC | D27: TECHNICOM | F27: Commercialization of the 4Gives System | G27: Mr. Varian Sherwin Chu Vashcorp, Inc. | I27: varianchu@gmail.com | J27: 5867730.2 | K27: STARTUP | L27: ONGOING | M27: EVFP
A28: 2019 | B28: NA | C28: PAC | D28: TECHNICOM 1.0 | F28: Product Design, Manufacturing and Field Scale Testing of StillFresh: Spoilage Monitoring Strip | G28: Mr. Joseph Christopher G. Doroja | I28: joseph.doroja@obf.ateneo.edu, etinhay@gmail.com | J28: 1636971 | K28: STARTUP
A29: 2019 | B29: NA | C29: PAC | D29: TECHNICOM 1.0 | F29: Integration of Data Science and Scaling Up of Payruler, a comprehensive Human Resource Management System (HRMS) | G29: Mr. Warlito Pio S. De Jesus | I29: jojo@geniihut.com, jojo@payruler.com, timmy@geniihut.com, timmy@payruler.com | J29: 3258768 | K29: STARTUP
A30: 2019 | B30: NA | C30: PAC | D30: TECHNICOM 1.0 | F30: Optimization of Virtual Reality Kit (VR Kit) for New Media Technology and Commercial Competitiveness | G30: Mr. Ryan Tan Yu | I30: ryan@mataverse.ph | J30: 4019382 | K30: STARTUP
A31: 2019 | B31: NA | C31: PAC | D31: TECHNICOM 1.0 | F31: Enhancement of the Micab Cab Hailing Engine thru Big Data Analytics | G31: Mr. Kenneth Baylosis | J31: 3135851.2 | K31: STARTUP
A32: 2019 | B32: NA | C32: PAC | D32: TECHNICOM 1.0 | F32: Scale-up Manufacturing of Biotek-M Diagnostic Kits and Post Marketing for Third Party Evaluation | G32: Dr. Raul V. Destura Denise Lacuna | I32: rvdestura@up.edu.ph jadelacuna12@gmail.com | J32: 16926594 | K32: STARTUP
A33: 2019 | B33: NA | C33: PAC | D33: TECHNICOM 1.0 | F33: Technology Enhancement and Commercialization of Exora Intellex as an Energy Analytics Machine Learning Platform for Industrial Smart Energy Management and Electricity Cost Reduction | G33: Mr. Sergius Angelo Santos Exora Technologies, Inc. | I33: sergius@exora.ph | J33: 4394800 | K33: STARTUP
A34: 2018 | B34: NA | C34: PAC | D34: TECHNICOM 1.0 | F34: Optimization of an Industry Grade Prototype of Po Lite Products | G34: Dr. Ria Liza Canlas | I34: riadear21@yahoo.com | J34: 4999045 | K34: STARTUP
A35: 2018 | B35: NA | C35: PAC | D35: TECHNICOM 1.0 | F35: Pilot Testing of a Deepwater Operation 3D Visual Mapping and Inspection System (PD-DOMAINS) | G35: Mr. Francis James Corpuz ANTIPARA Exploration Inc. | I35: franciscorpuz@gmail.com | J35: 3058155.2 | K35: STARTUP
A36: 2018 | B36: NA | C36: PAC | D36: TECHNICOM 1.0 | F36: Development of an Alternative Credit Scoring Model applying Machine Learning in Financing Farmers | G36: Mr. Ruel T. Amparo Cropital Enterprises Corporation | I36: ruel@cropital.com | J36: 3551018 | K36: STARTUP
A37: 2017 | B37: NA | C37: PAC | D37: TECHNICOM 1.0 | F37: Enhancement of Prototype and Market Readiness of R-TAP (an advanced pressure management system for water utilities) | G37: Mr. Stephen Larcia Hiraya Technology Solutions, Inc. | I37: stephen@hirayatech.ai; info@hirayatech.ai (02) 8826 6836 | J37: 4294326.4 | K37: STARTUP
A38: 2017 | B38: NA | C38: PAC | D38: TECHNICOM 1.0 | F38: Field Testing and Technology Validation of the E-Procurement Sytem (ePS) for Government Agencies | G38: Engr. Jose Rizaldy G. Harder Infodynamics Technologies | I38: (033) 321 0928 rizaldyharder@yahoo.com | J38: 1892235 | K38: STARTUP
A39: 2016 | B39: NA | C39: PAC | D39: TECHNICOM 1.0 | F39: Cost Efficient and High Quality Accelerograph for Disaster Preparedness in Buildings | G39: Mr. Rodolfo Alfonso (Ryan) Sabio Tekton Geometrix, Inc. | I39: 437-7001/ 0915 256 3355 | J39: 4736242.4 | K39: STARTUP
A40: 2025 | B40: NA | C40: NA | D40: EIPRAP | F40: Enhancement, Market Validation and Pilot Production of AI-Driven Farm Management Module (AID-FMM) | G40: Waste4good Research and Experimental Development in Engineering and Technology | I40: lurelynpablo@gmail.com lorilyn.daquioag@eee.upd.edu.ph 639385504997 | K40: STARTUP
...

Sheet IDD-Projects (2018-2025)
A1: Year | B1: Resolution No: | C1: Type | D1: Program | E1: Project Title | F1: Name of Proponent | G1: Amount of Investment
A2: 2025 | B2: 45901 | C2: APPROVAL | D2: GALING | E2: Flamethrower Device As Insects, Pests, Diseases, And Weed Controller | F2: MR. PHILIP G. CHAN 13 Rimando Road, Baguio City philipchan5762@gmail.com 09854791420 | G2: 81439.68
A3: 2025 | B3: 45931 | C3: APPROVAL | D3: ISP | E3: Invent School™ Program Seminar-Workshop for High School Students of Allen National High School | F3: Allen National High School, Allen Northern Samar | G3: 110000
A4: 2025 | B4: 45962 | C4: APPROVAL | D4: ISP | E4: Invent School™ Program Seminar-Workshop for Elementary Pupils of Paaralang Sentral ng Talaga | F4: DepEd City Schools Division of Tanuan | G4: 21000
A5: 2025 | B5: 2025-17 | C5: APPROVAL | D5: GALING | E5: Fabrication, and Installation of a 50W LED Flood Light Post with Integration of Small-scale Savonius-Type Helical Vertical Axis Wind Turbine (VAWT) and Solar Panel | F5: Engr. Jose Luis L. Villalon 25 Mercury, Zytek-Riosa, Brgy. Pasong Tamo, Quezon City, 1107 louie.vdaliinnovations@gmail.com +63 915 126 5571 | G5: 358538 | H5: STARTUP
A6: 2025 | B6: 2025-18 | C6: APPROVAL | D6: GALING | E6: Magicbag: Wireless slow cooker | F6: Ms. Rowena Faith Armeniana Sucalit 4423 Montojo St. Tejeros, Makati City weng747@yahoo.com 0916-777-8031 | G6: 229654 | H6: STARTUP
A7: 2025 | B7: 2025-19 | C7: APPROVAL | D7: ISP | E7: Invent School™ Program Seminar-Workshop for Grade 11 Students from De La Salle University- Dasmariñas High School | F7: De La Salle University- Dasmariñas High School | G7: 75000
A8: 2025 | B8: 2025-20 | C8: APPROVAL | D8: ISP | E8: Invent School™ Program Seminar-Workshop: DBTI Computer Society & EE-nnovators Club Members | F8: Don Bosco Technical Institute of Makati | G8: 65000
A9: 2025 | B9: 2025-21 | C9: APPROVAL | D9: ISP | E9: Invent School™ Program Seminar-Workshop for BaliwagHenyo Innovators | F9: BALHCEI Baliwag South Central School | G9: 75000
A10: 2025 | B10: 2025-26 | C10: APPROVAL | D10: GALING | E10: Market Validation of the Improved Cocoon and Other Materials Dryer | F10: First Road, Benin Lot 5, Pinsao Proper, Baguio City fiscar.cordillera@gmail.com 09065740108 | G10: 263282.5
A11: 2025 | B11: 2025-31 | C11: APPROVAL | D11: eIPRAP | E11: Internationally - Secured Patents for ASTI's Readiness on Commercialization (i-SPARC) 2025 | F11: DOST-ASTI | G11: 4990000
A12: 2025 | B12: 2025-32 | C12: APPROVAL | D12: GALING | E12: Technology Validation of Lapan Pork Sausage | F12: Dr. Marielle S. Dizon | G12: 197490.2
A13: 2024 | B13: 45444 | C13: APPROVAL | D13: ISP | E13: INVENT SCHOOL PROGRAM SEMINAR-WORKSHOP FOR COLLEGE STUDENTS IN SAINT LOUIS UNIVERSITY-MAIN CAMPUS,BAGUIO CITY ON JANUARY 27, 2024 | F13: SAIN LOUIS UNIVERSITY, BAGUIO CITY,BENGUET | G13: 18900
A14: 2024 | B14: 45505 | C14: APPROVAL | D14: ISP | E14: INVENT SHCOOL PROGRAM SEMINAR FOR COLLEGE STUDENTS IN CENTRAL MINDANAO UNIVERSITY (CMU)-MUSUAN, MARAMAG,BUKIDNON | F14: COLLEGE STUDENT IN CENTRAL MINDANAO UNIVERSITY(CMu) | G14: 122000
A15: 2024 | B15: 45536 | C15: APPROVAL | D15: ISP | E15: INVENT SCHOOL PROGRAM SEMINAR FOR JUNIOR AND SENIOR HIGH SCHOOL STUDENT OF IMUS INSTITUTE OF SCIENCE AND TECHNOLOGY AT IMUS CAVITE | F15: IMUS INSTITUTE OF SCIENCE AND TECHNOLOGY(IIST) | G15: 8000
A16: 2024 | B16: 45566 | C16: APPROVAL | D16: GALING | E16: TECHNOLOGY VALIDATION OF PORTABLE ABACA FIBER STRIPPING MACHINE | F16: MR. RAMON T. MANLOLO | G16: 227925
A17: 2024 | B17: 45597 | C17: APPROVAL | D17: ISP | E17: Invent School Program Seminar for College Students in the Selected Province of Pampanga | F17: DOST III PSTO-Pampanga | G17: 77500
A18: 2024 | B18: 45627 | C18: APPROVAL | D18: ISP | E18: Invent School Program Seminar-Workshop High School Level for Bolbok Integrated National High School | F18: DOST PSTO-BATANGAS | G18: 51300
A19: 2024 | B19: 2024-14 | C19: APPROVAL | D19: GALING | E19: Improved Cocoon and Other Materials Drye | F19: MR. GLEN M. PORTUGAL First Road, Benin Lot 5, Pinsao Proper, Baguio City 09065740108 fiscar.cordillera@gmail.com | G19: 32252
A20: 2024 | B20: 2024-16 | C20: APPROVAL | D20: ISP | E20: Invent School Program Seminar for College Students of Marikina Polytechnic College | F20: Marikina Polytechnic College | G20: 60000
A21: 2024 | B21: 2024-17 | C21: APPROVAL | D21: GALING | E21: Technology Validation of Carrot Smoothies with Blue Ternate Flower Infusion - GALING Program | F21: MS. LINA T. CODILLA B3, L5, Alta Tierra, Napolan, Pagadian City, Zamboanga Del Sur 09460668556 ltcodilla2018@gmail.com | G21: 71385
A22: 2024 | B22: 2024-21 | C22: APPROVAL | D22: ISP | E22: ISP in Eastern Samar | F22: Eastern Samar State University | G22: 76000
A23: 2024 | B23: 2024-22 | C23: APPROVAL | D23: ISP | E23: Invent School Program - Palawan | F23: Schools Division of Puerto Princesa City -Puerto Princesa City National Science High Schoolversity | G23: 111000
A24: 2024 | B24: 2024-36 | C24: APPROVAL | D24: GALING | E24: Technology Validation of Unas Canvas (UnVas) | F24: Julienne Fabie-Agapin Lumbia District, Pagadian City juliennestephanie.agapin@wmsu.edu.ph 09362660139 | G24: 43250 | H24: STARTUP
A25: 2024 | B25: 2024-42 | C25: APPROVAL | D25: ISP | E25: Invent School Program Seminar-Workshop for Selected Junior and Senior High School Students of Ateneo de Davao University | F25: Ateneo de Davao University-School of Engineering and Architecture | G25: 112800
A26: 2024 | B26: 2024-53 | C26: APPROVAL | D26: GALING | E26: Technology Validation of USB Port with Mounting Holder | F26: Mr. Alphy C. Ferraren Purok 4, Brgy.Gumaga, Libungan, North Cotabato bukid_31@yahoo.com 0970895069 | G26: 57667.56
A27: 2024 | B27: 2024-54 | C27: APPROVAL | D27: GALING | E27: Technology Validation of IOT Artificial Intelligence-Based Dosing System in Greenhouse | F27: Mr. Alvin Phoebe Artemis A. Valdez Interior Fidelidad Street, Barangay 1, Balayan, Batagas 4213 alvinphoebeartemis@gmail.com +639918781878; +639916453232 | G27: 236341.77 | H27: STARTUP
A28: 2024 | B28: 2024-55 | C28: APPROVAL | D28: Concept Proto | E28: Composing Machine with Rotary mixer | F28: Ms. Angelica A. Marcelino Topdac, Atok, Benguet 09384034199 angelicamarcelino49@gmail.com | G28: 186495.06
A29: 2024 | B29: 2024-56 | C29: APPROVAL | D29: Concept Proto | E29: Automated Air-reversible Agricultural Commodities Dryer | F29: Mr. Melvin B. Luteb Ampucao, Itogon, Benguet 09207160534/09926860643 luteb.melvin03@gmail.com | G29: 197182.36
A30: 2024 | B30: 2024-30 | C30: APPROVAL | D30: TECHNICOM | E30: Prototype Enhancement and Testing of Village-level Sago Pith Extracting Machine | F30: Engr. Aljon E. Bocobo Caraga State University | G30: 2344480 | H30: STARTUP
A31: 2024 | B31: 2024-71 | C31: APPROVAL | D31: TECHNICOM | E31: Automated Coconut Sap Extraction: Enhancing Productivity and Quality Through Innovative Technology | F31: Luzmar M. Gabor KASAKA Agriventures, Inc. | G31: 2998072 | H31: STARTUP
A32: 2024 | B32: 2024-78 | C32: APPROVAL | D32: TECHNICOM | E32: Enhancement and Market Validation of AI-Powered Property Management Solutions for the Philippines | F32: Mr. Jesehl Charles Basco Project Leader Collo/Proprty Technology Solutions Inc. | G32: 2911170 | H32: STARTUP
A33: 2024 | B33: 2024-63 | C33: APPROVAL | D33: ISP | E33: Invent School Program Seminar-Workshop for Elementary Pupils and Highschool Students in the Eastern Zone of Ilocos Norte | F33: DOST Regional Office I | G33: 119250
A34: 2024 | B34: 2024-64 | C34: APPROVAL | D34: GALING | E34: Technology Validation of Motorized Multi-Purpose Grater and Shredder | F34: Mr. Johnny D. Banez | G34: 105791
A35: 2024 | B35: 2024-82 | C35: APPROVAL | D35: TECHNICOM | E35: Enhancement, Market Validation, and Pilot Production of AI-Driven Farm Management Module (AID-FMM) | F35: Ms. Lorilyn P. Daquioag Project leader Waste4Good technologies | G35: 2384720 | H35: STARTUP
A36: 2024 | B36: 2024-38 | C36: APPROVAL | D36: TECHNICOM | E36: Field Testing and Market Validation of Cost-Efficient Solar-Power Navigating Paddle Wheel Aerotor System for Grow Out Farming | F36: JONELLE H. TABLADA / Male SOUTHEASTERN LEYTE STATEUNIVERSITY | G36: 2715984
A37: 2024 | B37: 2024-88 | C37: APPROVAL | D37: TECHNiCOM | E37: Improvement and Pilot Testing of Alerto PH AI-as-a-Service (AlaaS) | F37: Ms. Cristina Macaraig WiredField Philippines Inc. | G37: 2975715 | H37: STARTUP
A38: 2024 | B38: 2024-72 | C38: APPROVAL | D38: GALING | E38: Technology Validation of Ship Anti-piracy Fence Apparatus” of Mr. Nestor V. Buencido | F38: MR. NESTOR V. BUENCIDO
A39: 2024 | B39: 2024-74 | C39: APPROVAL | D39: TECHNICOM | E39: Market Testing of Online Residential Rental Marketplace for Filipino Students and Young Professionals | F39: Alyssa Casandra Wee Project Leader/ Krelio Technologies Inc. | G39: 2999945.7 | H39: STARTUP
A40: 2024 | B40: 2024-75 | C40: APPROVAL | D40: EIPRAP | E40: Cross-Border IP: Global IP Assessment and Filing in Forest Products Research and Development Institute (FPRDI) | F40: DOST-FPRDI | G40: 4180264
...

Sheet IBOD-Projects (2018-2025)
A1: Year | B1: Resolution No: | C1: Type | D1: Program | E1: Project Title | F1: Name of Proponent | G1: Amount of Investment
A2: 2025 | B2: 2025-13 | C2: APPROVAL | D2: I-TECH | E2: Expansion of the Commercialized Innovative Green Technology for Energy Conserving Industrial Oil Restoration Apparatus Services | F2: ENGR. REYNALDO RADEN ALDEPULLA Proprietor | G2: 4100000
A3: 2025 | B3: 2025-22 | C3: APPROVAL | D3: HIRANG 2.0 | E3: Concept Proposal for Cohort 3 for the HIRANG 2.0 Program Implementation | F3: Inventors and Startup beneficiaries of GALING and HEIs and SUC graduates of TECHNICOM | G3: 2500000
A4: 2025 | B4: 2025-29 | C4: APPROVAL | D4: eVFP | E4: Commercialization of GradeChum: An AI-Powered Platform for Automatic Evaluation of Handwritten Activities | F4: MR. JEMAR JUDE A. MARANGA President and CEO CODECHUM SOFTWARE SOLUTIONS INC. | G4: 4500000 | H4: STARTUP
A5: 2024 | B5: 2024-79 | C5: APPROVAL | D5: EVFP | E5: Bio-Based Polyurethene Adhesive System for Coconut Coir Board Production | F5: Kenno Michael M. Uy CEO Lesstics Inc | G5: 4551960 | H5: STARTUP
A6: 2024 | B6: 2024-51 | C6: APPROVAL | D6: EVFP | E6: Commercialization of Cerebro Plus: An Integrated School Management and Content Library System for k-12 Schools | F6: Jonald Justine U. Itugot Chief Executive Officer Cerebro Solutions, Inc. | G6: 3412000 | H6: STARTUP
A7: 2024 | B7: 2024-68 | C7: APPROVAL | D7: EVFP | E7: Enhance IP protection and Commercialization of Value-based Care Module of See You Doc Corp. under the Expanded VFP | F7: Mr. Noel Gary E. Del Castillo Founder and CEO | G7: 2332760.9 | H7: STARTUP
A8: 2024 | B8: 2024-58 | C8: APPROVAL | D8: EVFP | E8: Enhancement of BizKit (The First Local Centralized Business Suite) To Better Facilitate Cross-functional And Holistic Business Operations In The New Normal | F8: Marc Carlo Lijauco President BizKit Technologies Inc. | G8: 4000000 | H8: STARTUP
A9: 2024 | B9: 2024-60 | C9: APPROVAL | D9: EVFP | E9: HOCLOMAC: Product Certification, Inventory, and Sales | F9: Dr. Francis Aldrine A. Uy President and CEO USHER Technologies, Inc. | G9: 4143400.5 | H9: STARTUP
A10: 2024 | B10: 2024-87 | C10: APPROVAL | D10: EVFP | E10: Scale up of Fullmight Agricultural Corp. Operations and Product Certification | F10: Dr. Virginia M. Padilla Secretary and Treasurer Fullmight Agricultural Corp. | G10: 4771250 | H10: STARTUP
A11: 2024 | B11: 2024-84 | C11: APPROVAL | D11: EVFP | E11: Scale-Up Assistance for WEHLO Technologies, Inc. under E-VFP | F11: Dr. Cris Edward Monjardin Chief Technology Technology WEHLO Resilience Technology Corporation Inc. | H11: STARTUP
A12: 2024 | B12: 2024-35 | C12: APPROVAL | D12: HIRANG | E12: Honing Innovations, Research, Agreements and Negotiations of the Government - Funded Technologies* (HIRANG) 2.0 Program - Phase VI Implementation | F12: Technology generators, research, research teams, or TTBDOs of the DORT - RDI | G12: 705000
A13: 2024 | B13: 2024-90 | C13: APPROVAL | D13: EVFP | E13: Scale-up Operational Assistance to Hiraya Technology Solutions, Inc. | F13: Mr. Stephen L. Larcia Chief Executive Officer Hiraya Technology Solutions, Inc. | G13: 4000000 | H13: STARTUP
A14: 2024 | B14: 2024-45 | C14: APPROVAL | D14: HIRANG | E14: Concept Proposal for HIRANG 2.0 Cohort 2 Implementation | F14: Technology generators, researchers, research teams, or TTBDOs of the DOST-STS agencies, SUCs, and HEIs | G14: 2470750
A15: 2024 | B15: 2024-80 | C15: APPROVAL | D15: EVFP | E15: Scaleup of CHRG Inc. Operations and Product Certifications | F15: Engr. Leo Allen S. Tayo CEO and President CHRG Electric vehicle technologies Inc | G15: 5000000 | H15: STARTUP
A16: 2024 | B16: 2024-57 | C16: APPROVAL | D16: EVFP | E16: Scaling up for Market Expansion and Customer Retention | F16: Ms. Ralen Rose Gloria L. Malatbalat COO, making.technology Manufacturing Corporation | G16: 4668619.3 | H16: STARTUP
A17: 2024 | B17: 2024-59 | C17: APPROVAL | D17: HIRANG | E17: The PROPEL ENTERPRISE DEVELOPMENT Program | F17: DOST NCR DOST OASEC TTCC | G17: 5000000
A18: 2024 | B18: 2024-33 | C18: APPROVAL | D18: VFP | E18: Enhancing Manufacturing and Production Capacity through Raw Material Purchasing | F18: Charlou Delos Reyes Guion Proprietor CG Machine Shop | G18: 709948
A19: 2024 | B19: 2024-25 | C19: APPROVAL | D19: VFP | E19: Expanding Market Research-Enhancing Tonyts Food Products Growth with Strategic Raw Material Sourcing | F19: Ms. Antonitte C. Canda Proprietor Tonyts Food Products | G19: 333400
A20: 2024 | B20: 2024-50 | C20: APPROVAL | D20: VFP | E20: Purchase Order Financing for Danilyn's Enterprises, Inc.- Phase II | F20: Ms. Melinda C. Medallo Vice President/Marketing Head Danilyn's Enterprises, Inc. | G20: 1503651.6
A21: 2024 | B21: 2024-28 | C21: APPROVAL | D21: VFP | E21: Purchase Order Financing for Fondre Flavour Dynamics Vegetable Lumpiang Togue | F21: MR. GILBERT C. JIM CEO FONDRE FLAVOUR DYNAMICS, INC. | G21: 2000000
A22: 2024 | B22: 2024-70 | C22: APPROVAL | D22: VFP | E22: Strategic Raw Material Sourcing to Boost Manufacturing Efficiency for CAMPCO | F22: Mr. Noel B. Bacasnot Chairman CARAGA Adventists Multi-Purpose Cooperative (CAMPCO) | G22: 383657.4
A23: 2023 | B23: 45017 | C23: APPROVAL | D23: VFP | E23: PO Financing for Rockwell Enterprises for the delivery of DOST-ASTI Tsunami Early Warning System-Alerting Station Technology | F23: Mr. Alexis, Rellama, Rockwell Enterprises | G23: 380000
A24: 2023 | B24: 2023-20 | C24: APPROVAL | D24: VFP | E24: Purchase Order Financing for Danilyn’s’ Enterprises, Inc. | F24: Ms. Melinda C. Medallo Vice President/Marketing Head Danilyn’s Enterprises, Inc. | G24: 918215.51
A25: 2023 | B25: 2023-25 | C25: APPROVAL | D25: VFP | E25: PO Financing Program Support for Qualimeal Feedmills, Inc. | F25: Mr. Teotimo L. Reyes, Jr. President Qualimeal Feedmills, Inc. Banaybanay, San Vicente, Lipa City, Batangas | G25: 496800
A26: 2023 | B26: 2023-27 | C26: APPROVAL | D26: VFP | E26: Financing of Raw Materials Procurement of Ash Kitchen Trading and Marketing | F26: MS. GINA L. DELA CRUZ, Proprietor | G26: 556803.45
A27: 2023 | B27: 2023-31 | C27: APPROVAL | D27: VFP | E27: Venture Financing Program for Francis Jacob’s Gourmet Foods | F27: MS. IRENE D. HERRERO | G27: 1996038
A28: 2023 | B28: 2023-47 | C28: APPROVAL | D28: VFP | E28: Labo Progressive Multi-Purpose Cooperative Integrated Pineapple Processing and Marketing Enterprise (LPMPC-IPPME) QUEENCH Products Market Development and Productivity Enhancement | F28: Mr. Rey Ulysses L. Dimaano | G28: 163174.5
A29: 2023 | B29: 2023-49 | C29: APPROVAL | D29: VFP | E29: TAPI Purchase Order Financing Phase 1 for Mama Jita's Food Products | F29: Ms. Julieta Butalid-Dela Cerna | G29: 500000
A30: 2023 | B30: 2023-50 | C30: APPROVAL | D30: VFP | E30: Raw Materials for Continuous Disc Dryer | F30: Mr. Manuel P. Galut, Jr | G30: 1493838
A31: 2023 | B31: 2023-52 | C31: APPROVAL | D31: VFP | E31: Venture Financing Program Assistance for Soyuz Foods International Inc | F31: Ms. Helena H. Del Rosario | G31: 1240000
A32: 2023 | B32: 2023-53 | C32: APPROVAL | D32: VFP | E32: Venture Financing Program of RS Unitech Manufacturing and Trading Corporation | F32: Ms. Edralin Lagajino | G32: 249255
A33: 2023 | B33: 2023-55 | C33: APPROVAL | D33: VFP | E33: Venture Financing for Raw Materials of V. Weisz Synergy, Inc. | F33: Ms. Victoria Y. Bulan, President | G33: 1652388.5
A34: 2023 | B34: 2023-60 | C34: APPROVAL | D34: VFP | E34: Acquisition of Raw Materials to Enhance the Competitiveness and Sustainability of LNA DietCare’s Operation in Sibulan, Negros Oriental | F34: Ms. Leila N. Aclaro, RND Proprietor/Manager LNA DietCare | G34: 369166.12
A35: 2023 | B35: 2023-61 | C35: APPROVAL | D35: VFP | E35: Product Expansion of Affection8 Consumer Goods Trading through Acquisition of Venture Financing | F35: Ms. Monica Sandra Carino-Ronda | G35: 309847.12
... A40: 2022 | B40: 2022-34 | C40: APPROVAL | D40: VFP | E40: Commercialization of Hydrogen Fuel System | F40: KCH R&D Corporation | G40: 702000
A41: 2022 | B41: 2022-37 | C41: APPROVAL | D41: ITECH | E41: The Utilization of Calcium Hydroxide and Clinoptilolite Disinfectant PH12 of Hydrogen to Alleviate the Prevalence of Dengue in the Philippines | F41: Mr. Lyle Christian R. Herbosa
A42: 2022 | B42: 2022-45 | C42: APPROVAL | D42: VFP | E42: PO Financing Phase 2 for John N' Mico Food Productes | F42: Ms. Myra M. Bustillo, Owner/Manager | G42: 923252
A43: 2022 | B43: 2022-46 | C43: APPROVAL | D43: VFP | E43: PO Financing for La Paz Prime Foods Corporation | F43: Ms. Virgin Mary A. Nicolas, President | G43: 494868.75
A44: 2022 | B44: 2022-53 | C44: APPROVAL | D44: VFP | E44: PO Financing Assistance to SETUP assisted Kalinga Blend Roasted Ground Coffee Production" with "MAP Guidelines | F44: Ms. Grace B. Agtina, Owner | G44: 998550
...

Sheet Copy of TIPD_STARTUPS
A1: Year | B1: Resolution No: | C1: TYPE | D1: Program Applied | E1: PROMOTIONAL ASSISTANCE | F1: Approval Date | G1: Project Title | H1: Name of Proponent | I1: Address | J1: Contact Details | K1: Amount | L1: CLASS | M1: STATUS | N1: POSSIBLE FOLLOW UP ASSITANCE
A2: 2025 | C2: PROMOTION | D2: EIPRAP | E2: Market Intelligence under IMPAKT | F2: 2025 | G2: Enhancement, Market Validation and Pilot Production of AI-Driven Farm Management Module (AID-FMM) | H2: Waste4good Research and Experimental Development in Engineering and Technology | J2: lurelynpablo@gmail.com lorilyn.daquioag@eee.upd.edu.ph 639385504997 | L2: STARTUP | M2: ONGOING
A3: 2024 & 2025 | C3: PROMOTION | D3: EIPRAP | E3: WoSG, E-MarkET Market Intelligence, CES 2025 | F3: 2024 & 2025 | G3: High-resolution 3D Geological Mapping with Ambient Electromagnetic Interferometry | H3: Emmanuel G. Ramos Mark Linus C. Ramos Rodolfo Alfonso R. Sabio | L3: STARTUP | M3: ONGOING
A4: 2025 | C4: PROMOTION | D4: EIPRAP | E4: IEIG 2025, PHILIPPiNEXT | F4: 2025 | G4: A System and Method for Managing Healthcare Services and Networks | H4: SeeYouDoc Corporation | J4: noel@seeyoudoc.com | L4: STARTUP | M4: ONGOING
A5: 2025 | B5: 2025-29 | C5: PROMOTION | D5: EVFP | G5: Commercialization of GradeChum: An AI-Powered Platform for Automatic Evaluation of Handwritten Activities | H5: MR. JEMAR JUDE A. MARANGA President and CEO CODECHUM SOFTWARE SOLUTIONS INC. | I5: 753 Katipunan St., Tisa, Cebu City, Cebu, Philippines | J5: jude@codechum.com 639959469610 | K5: 4500000 | L5: STARTUP | M5: ONGOING
A6: 2024 | B6: 2024-79 | C6: PROMOTION | D6: EVFP | E6: IEIG 2025 / RSTW VIII | F6: 2025 | G6: Bio-Based Polyurethene Adhesive System for Coconut Coir Board Production | H6: Kenno Michael M. Uy CEO Lesstics Inc | I6: 0014 Matthew St. Bahayan, Luinab, Iligan City | J6: Cell No.: 0917-162-2127 Email: lesstics@gmail.com | K6: 4551960 | L6: STARTUP | M6: ONGOING
A7: 2024 | B7: 2024-60 | C7: PROMOTION | D7: EVFP | E7: WoSG, CES 2025, E-MarkET Market Intelligence | F7: 2024 | G7: HOCLOMAC: Product Certification, Inventory, and Sales | H7: Dr. Francis Aldrine A. Uy President and CEO USHER Technologies, Inc. | I7: 1409 Corporate 145, Mother Ignacia St., South Triangle, Quezon City | J7: drfrancisuy@gmail.com | K7: 4143400.5 | L7: STARTUP | M7: ONGOING
A8: 2024 | B8: 2024-51 | C8: PROMOTION | D8: EVFP | G8: Commercialization of Cerebro Plus: An Integrated School Management and Content Library System for k-12 Schools | H8: Jonald Justine U. Itugot Chief Executive Officer Cerebro Solutions, Inc. | J8: justine@cerebro.ph +63 917 886 5402 | K8: 3412000 | L8: STARTUP | M8: ONGOING
A9: 2024 | B9: 2024-68 | C9: PROMOTION | D9: EVFP | G9: Enhance IP protection and Commercialization of Value-based Care Module of See You Doc Corp. under the Expanded VFP | H9: Mr. Noel Gary E. Del Castillo Founder and CEO | J9: noel@seeyoudoc.com | K9: 2332760.9 | L9: STARTUP | M9: ONGOING
A10: 2024 | B10: 2024-58 | C10: PROMOTION | D10: EVFP | G10: Enhancement of BizKit (The First Local Centralized Business Suite) To Better Facilitate Cross-functional And Holistic Business Operations In The New Normal | H10: Marc Carlo Lijauco President BizKit Technologies Inc. | I10: 96 Burgos St. Pamplona Uno Las Piñas City 1740 | J10: mclijauco@bizkittechnologies.com | K10: 4000000 | L10: STARTUP | M10: ONGOING
A11: 2024 | B11: 2024-87 | C11: PROMOTION | D11: EVFP | G11: Scale up of Fullmight Agricultural Corp. Operations and Product Certification | H11: Dr. Virginia M. Padilla Secretary and Treasurer Fullmight Agricultural Corp. | I11: 6th Street, 1856 Hillside Village Subdivision, Brgy. Tuntungin-Putho, Los Baños Laguna | J11: Tel. no.: (049) 508-0557 CP no.: 0917-887-8542, 0917-179-8542 Email: padilla7.jaime@gmail.com, virgiem.padilla@gmail.com | K11: 4771250 | L11: STARTUP | M11: ONGOING
A12: 2024 | B12: 2024-84 | C12: PROMOTION | D12: EVFP | E12: CES 2025, Handa Pinas 2025 | F12: 2025 | G12: Scale-Up Assistance for WEHLO Technologies, Inc. under E-VFP | H12: Dr. Cris Edward Monjardin Chief Technology Technology WEHLO Resilience Technology Corporation Inc. | I12: Unit 1409, Corporate 145, 145 Mother Ignacia St., Brgy. South Triangle, Quezon City | J12: 09692314619 cefmonjardin@mapua.edu.ph | K12: 4.975,000.00 | L12: STARTUP | M12: ONGOING
A13: 2024 | B13: 2024-90 | C13: PROMOTION | D13: EVFP | E13: WoSG, CES 2025, DOST-TAPI and APCTT event Sept 3-4, 2024 , Handa Pinas 2025 | F13: 2024 & 2025 | G13: Scale-up Operational Assistance to Hiraya Technology Solutions, Inc. | H13: Mr. Stephen L. Larcia Chief Executive Officer Hiraya Technology Solutions, Inc. | I13: 502-503 Jocfer Building, Commonwealth Ave., Quezon City | J13: Cell No.: (02) 8826 6836 Email: stephen@hirayatech.ai; info@hirayatech.ai | K13: 4000000 | L13: STARTUP | M13: ONGOING
A14: 2024 | B14: 2024-80 | C14: PROMOTION | D14: EVFP | E14: E-MarkET WoSG Market Intelligence, NICE, CES 2025, APCTT 2024 Exhibit, Philippinext | F14: 2024 & 2025 | G14: Scaleup of CHRG Inc. Operations and Product Certifications | H14: Engr. Leo Allen S. Tayo CEO and President CHRG Electric vehicle technologies Inc | I14: 3F, Enterprise Incubation Room, National Engineering Center, Osmena Ave, UP Campus, Diliman, Quezon City. | J14: Engr. Leo Allen S. Tayo – 09272103449 Engr. Rovinna Janel Tayo – 09297193619 leo@chrg.tech / janel@chrg.tech | K14: 5000000 | L14: STARTUP | M14: ONGOING
A15: 2024 | B15: 2024-57 | C15: PROMOTION | D15: EVFP | G15: Scaling up for Market Expansion and Customer Retention | H15: Ms. Ralen Rose Gloria L. Malatbalat COO, making.technology Manufacturing Corporation | I15: UPSCALE G/F National Engineering Center, F. Agoncillo St., cor. Osmena Ave., U.P. Campus, Diliman, Quezon City, 1101 | J15: ralen@makingtech.co / inquire@makingtech.co | K15: 4668619.3 | L15: STARTUP | M15: ONGOING
A16: 2022 | B16: 2022-109 | C16: PROMOTION | D16: ITECH | E16: Marketing Assistance Program, SIIF | F16: 2024 | G16: Commercialization of Maker-scope | H16: MR. JEREMY C. DE LEON | J16: jeremycdeleon@gmail.com | K16: 1083679 | L16: STARTUP | M16: COMPLETED
A17: 2018 | C17: PROMOTION | D17: IBED | E17: Marketing Assistance Program, LUNDUYAN | F17: 2022 | G17: Alkaline Fuel Cell For Various Applications | H17: Roderick Nicolas | J17: hydrogenprolife@gmail.com | M17: COMPLETED
A18: 2018 | C18: PROMOTION | D18: IBID | E18: Marketing Assistance Program | F18: 2022 | G18: Foldable Crutch System | H18: James Bryan Camacho | J18: jabecmacho@gmail.com | M18: COMPLETED
A19: 2018 | C19: PROMOTION | D19: IBED-I | E19: Marketing Assistance Program | F19: 2022 | G19: Simplified Compact Tire Inverter Machine | H19: Lester A. Quimpo | J19: lesterquimpo@yahoo.com | M19: COMPLETED
A20: 2018 | C20: PROMOTION | D20: IBED-I | E20: Marketing Assistance Program | F20: 2022 | G20: Green Eco-Toilet System (GETS) | H20: Daniel A. Camacho | J20: greenway.ts@gmail.com | M20: COMPLETED
A21: 2025 | C21: PROMOTION | D21: GALING | E21: LUNDUYAN KIWIE, Marketing Assistance Program | F21: 2024 | G21: Magicbag: Wireless slow cooker | H21: Ms. Rowena Faith Armeniana Sucalit 4423 Montojo St. Tejeros, Makati City | J21: weng747@yahoo.com 0916-777-8031 | K21: 229654 | L21: STARTUP | M21: ONGOING | N21: GALING (Market Validation)
A22: 2024 | C22: PROMOTION | D22: GALING | E22: PHILIPPiNEXT | F22: 2025 | G22: Marissa Turbine: Vertical-Axis Tidal Turbine | H22: Mr. Patrick Roland de Guzman 65 Lawa, Obando, Bulacan | J22: deguzmanpatrickroland@gmail.com 09974916634 | K22: 395212 | L22: STARTUP | M22: ONGOING
A23: 2024 | C23: PROMOTION | D23: GALING | E23: PHILIPPiNEXT, Marketing Assistance Program, KIWIE, LUNDUYAN | F23: 2024 | G23: Technology Validation of Unas Canvas (UnVas) | H23: Julienne Fabie-Agapin Lumbia District, Pagadian City | J23: juliennestephanie.agapin@wmsu.edu.ph 09362660139 | L23: STARTUP | M23: COMPLETED
A24: 2024 | C24: PROMOTION | D24: GALING | E24: PHILIPPiNEXT | F24: 2025 | G24: Technology Validation of IOT Artificial Intelligence-Based Dosing System in Greenhouse | H24: Mr. Alvin Phoebe Artemis A. Valdez Interior Fidelidad Street, Barangay 1, Balayan, Batagas 4213 | J24: alvinphoebeartemis@gmail.com +639918781878; +639916453232 | K24: 236341.77 | L24: STARTUP | M24: ONGOING
A25: 2023 | C25: PROMOTION | D25: GALING | E25: LUNDUYAN, Marketing Assistance Program | F25: 2024 | G25: Improved KoolGear | H25: Mr. Ivan Brent Nara Bldg. 23, UP Bliss, Diliman, Quezon City | J25: naraivanbrent@gmail 09751905598 | K25: 96107 | L25: STARTUP | M25: ONGOING
A26: 2023 | C26: PROMOTION | D26: GALING | E26: Marketing Assistance Program, KIWIE | F26: 2024 | G26: Foldable Water Tank with Zeramic Filter | H26: Ms. Eleanor M. Olegario | I26: 17 Cavite Street, Bonifacio Village, Brgy. Pasong Tamo, Quezon City | J26: eleanor.olegario@gmail.com 09209129187 | K26: 191500 | L26: STARTUP | M26: COMPLETED
A27: 2023 | C27: PROMOTION | D27: GALING | E27: PHILIPPiNEXT, Marketing Assistance Program, CES 2025, SIIF | F27: 2024, 2025 | G27: Technology Validation of Pili Seal | H27: Engr. Mark Kennedy E. Bantugon | J27: markkennedy09bantugon@gmail.com andpili.adheseal@gmail.com | K27: 349799.56 | L27: STARTUP | M27: ONGOING
A28: 2025 | C28: PROMOTION | D28: GALING | G28: Fabrication, and Installation of a 50W LED Flood Light Post with Integration of Small-scale Savonius-Type Helical Vertical Axis Wind Turbine (VAWT) and Solar Panel | H28: Engr. Jose Luis L. Villalon | I28: 25 Mercury, Zytek-Riosa, Brgy. Pasong Tamo, Quezon City, 1107 | J28: louie.vdaliinnovations@gmail.com +63 915 126 5571 | K28: 358538 | L28: STARTUP | M28: ONGOING
A29: 2023 | C29: PROMOTION | D29: GALING | E29: Marketing Assistance Program, LUNDUYAN | F29: 2024 | G29: LanaSug Cooking Oil | H29: AL-ANNI A. ASGALI | J29: farshaniasgali@gmail.com | M29: ONGOING
A30: 2023 | C30: PROMOTION | D30: GALING | E30: Marketing Assistance Program, LUNDUYAN | F30: 2024 | G30: Motorized Multi-Purpose Machine | H30: Johnny Banez | J30: johnnybanez1@gmail.com | M30: ONGOING
A31: 2023 | C31: PROMOTION | D31: GALING | E31: Marketing Assistance Program, LUNDUYAN | F31: 2024 | G31: Technology Validation of Pili Seal | H31: Engr. Mark Kennedy E. Bantugon | J31: markkennedy09bantugon@gmail.com | L31: STARTUP | M31: ONGOING
A32: 2023 | C32: PROMOTION | D32: GALING | E32: Marketing Assistance Program, LUNDUYAN | F32: 2024 | G32: Channel Multiplier Remote Control System – Prototype 3 | H32: Mr. Gibsonjis Rosales | J32: gibsonjisrosales@gmail.com | M32: ONGOING
A33: 2023 | C33: PROMOTION | D33: GALING | E33: Marketing Assistance Program, LUNDUYAN | F33: 2024 | G33: Alpha Herbal Oil | H33: Ms. Mariecel A. Fuentes | J33: Mariecel.fuentes30@gmail.com
A34: 2023 | C34: PROMOTION | D34: GALING | E34: Marketing Assistance Program | F34: 2024 | G34: Improved KoolGear | H34: Mr. Ivan Brent Nara | J34: naraivanbrent@gmail.com | L34: STARTUP
A35: 2023 | C35: PROMOTION | D35: GALING | E35: Marketing Assistance Program, LUNDUYAN | F35: 2024 | G35: Innovation support for Pre-commercialization of Abaca Fiber Tiles: a locally developed product utilizing Abaca wastes | H35: Mr. Jay F. Sanchez | J35: jsanchez372000@yahoo.com
A36: 2023 | C36: PROMOTION | D36: GALING | E36: Marketing Assistance Program, LUNDUYAN | F36: 2024 | G36: Foldable Water Tank with Zeramic Filter | H36: Ms. Eleanor M. Olegario | J36: lithos.opc.2021@gmail.com | L36: STARTUP
A37: 2025 | C37: PROMOTION | D37: TECHNICOM | G37: Commercialization and Scaling of Duon’s Real-Time Indoor Navigation with Foot Traffic Behavioral Analysis and Prediction AI | H37: MR. GABRIEL ANTON D. ANGELES, Project Leader DUON TECHNOLOGIES INCORPORATED | I37: 7F, Panorama Tower 34th Street, corner Lane A, Taguig, 1634 Metro Manila | J37: gda4993@gmail.com, admin@duon.ph 9773470628 | K37: 7175464 | L37: STARTUP | M37: ONGOING
A38: 2025 | C38: PROMOTION | D38: TECHNICOM | E38: PHILIPPiNEXT | F38: 2025 | G38: COMMERCIAL PROTOTYPING OF SMART WATER (IOT) METER (SWIM) | H38: CONRADO D. CAMILON JR, Project Leader ALEXA’S ENGINEERING SERVICES | J38: cdcamilonjr@gmail.com 09224074861/049-501-4583 | K38: 4998689 | L38: STARTUP | M38: ONGOING
A39: 2025 | C39: PROMOTION | D39: TECHNICOM | E39: PHILIPPiNEXT | F39: 2025 | G39: Rezbin: Business Model Validation and Market Acceptability Testing for Low Cost AI-powered Bins as an Alternative to Expensive Reverse Vending Machines in Metro Manila | H39: Matthew Cristi C. Martirez, Project Leader Rezbin Waste Technology Inc. | J39: mari@rezbin.ph, hello@rezbin.ph 639178920234 | K39: 4999988 | L39: STARTUP | M39: ONGOING
A40: 2025 | C40: PROMOTION | D40: TECHNICOM | G40: Technological Improvement and Field Testing of Bamboo-based Biodegradable Period Care | H40: Alexandra B. Jocom, Project Leader BioTerra Corp. (Halia) | J40: alexa@halia.co 639764896618 | K40: 5000000 | L40: STARTUP | M40: ONGOING
...

Sheet TIPD-Projects (2018-2025)
A1: Year | B1: Resolution No: | C1: Type | D1: Program | E1: Project Title | F1: Name of Proponent | G1: Amount of Investment
A2: 2025 | B2: 45778 | C2: APPROVAL | D2: IMPAKT | E2: 50th Geneva International Exhition of Inventions | F2: Identified 2024 NICE Winners, DOST-attached agencies, and DOST-funded/supported Startups and Universities | G2: 2535792
A3: 2025 | B3: 2025-23 | C3: APPROVAL | D3: LEAD | E3: 2025 MIMAROPA Regional Science, Technology, and Innovation Week Celebration | F3: DOST-MIMAROPA | G3: 200000
A4: 2025 | B4: 2025-25 | C4: APPROVAL | D4: IMPAKT | E4: Proposal for DOST-TAPI GFPS Promotional Campaign "Lahat tayo, POSIBLE" | F4: DOST-TAPI External Clients
A5: 2025 | B5: 2025-27 | C5: APPROVAL | D5: LEAD | E5: Conduct of the 2025 Clusterized Regional Invention Contest and Exhibits (ClusteRICE) | F5: DOST-Regional Offices and ClusteRICE participants, and stakeholders
A6: 2025 | B6: 2025-28 | C6: APPROVAL | D6: LEAD | E6: 2025 Regional Science Technology and Innovation Week (RSTiW) Celebration in the Cordillera Administrative Region | F6: DOST-Cordillera Administrative Region (DOST- CAR) | G6: 300000
A7: 2025 | B7: 2025-33 | C7: APPROVAL | D7: LEAD | E7: 2025 HANDA PILIPINAS SA BAGONG PILIPINAS: Innovations in Climate and Disaster Resilience Nationwide Exposition 2025 | F7: DOST-TAPI, LEAD Unit | G7: 1300000
A8: 2025 | B8: 2025-34 | C8: APPROVAL | D8: IMPAKT | E8: Indonesia Inventors’ Day 2025 | F8: NICE Winners and DOST-funded/supported Start-ups
A9: 2025 | B9: 2025-35 | C9: APPROVAL | D9: LEAD | E9: 2025 Regional Science, Technology, and Innovation Week Celebration in Bicol: "Building a Smart and Sustainable Communities | F9: DOST-Region V | G9: 300000
A10: 2025 | B10: 2025-37 | C10: APPROVAL | D10: IMPAKT | E10: 2025 Gawad Alunig x Dalumat | F10: DOST-TAPI TIPD
A11: 2025 | B11: 2025-38 | C11: APPROVAL | D11: LEAD | E11: 2025 Regional Science, Technology, and Innovation Week (RSTW) Celebration in the Region VII | F11: DOST-Region VIII | G11: 300000
A12: 2024 | B12: 2024-13 | C12: APPROVAL | D12: CIMU | E12: 49TH GENEVA INTERNATIONAL EXHIBITION OF INVENTIONS | F12: IDENTIFIED DOST-TAPI NICE WINNER AND DOST-ATTACHED AGENCIES | G12: 2865280
A13: 2024 | B13: 2024-18 | C13: APPROVAL | D13: CIMU | E13: WorldInvent Singapore 2024 | F13: Identified Filipino inventors and innovators,DOST RDIs and Technicom starup | G13: 1580913
A14: 2024 | B14: 2024-19 | C14: APPROVAL | D14: SCUPRU | E14: 2024 National Invention Contest and Exhibits (NICE) | F14: ISTE Program,TIPD DOST-TAPI Bicutan, Taguig | G14: 1307000
A15: 2024 | B15: 2024-20 | C15: APPROVAL | D15: ISTE | E15: 2024 Regional Science and Technology Week IVB | F15: DOST-MIMAROPA | G15: 200000
A16: 2024 | B16: 2024-29 | C16: APPROVAL | D16: ISTE | E16: 2024 Regional Science Technology and Innovation Week (RSTW) Celebration in Region I | F16: DOST Region I | G16: 300000
A17: 2024 | B17: 2024-32 | C17: APPROVAL | D17: ISTE | E17: 2024 Regional Science Technology and Innovation Week (2024 RSTW) | F17: DOST Region VIII | G17: 200000
A18: 2024 | B18: 2024-40 | C18: APPROVAL | D18: SCUPRU | E18: 2024 Gawad Alunig x Dalumat | F18: DOST-NCR | G18: 631500
A19: 2024 | B19: 2024-41 | C19: APPROVAL | D19: ISTE | E19: 2024 Regional Science Technology, and Innovation Week(RSTW) Celebration in the Cordillera Administrative Region | F19: DOST-CAR | G19: 300000
A20: 2024 | B20: 2024-43 | C20: APPROVAL | D20: CIMU | E20: National Science and Technology Fair (NSTF) Thailand 2024 | F20: Indentified Filipino Inventors and Innovators, DOST RDIs | G20: 266000
A21: 2024 | B21: 2024-44 | C21: APPROVAL | D21: ISTE | E21: Fabrication of Booth System for the Conduct of RSTiW | F21: DOST-II | G21: 300000
A22: 2024 | B22: 2024-47 | C22: APPROVAL | D22: ISTE | E22: Regional Forum on Innovative and Emerging Technologies to Address Climate Change and Workshop on Strategic Approaches to Assessing Market Potential for Technology Innovations | F22: UN-APCTT | G22: 1652500
... A27: 2024 | B27: 2024-67 | C27: APPROVAL | D27: ISTE | E27: Exhibit Space Registration for the Consumer Electronic Show (CES 2025) | F27: Consumer Technology Association, CES 2025 | G27: 4050000
A28: 2023 | B28: 44958 | C28: APPROVAL | D28: ACU-I | E28: ACU-i Campaign 2023 | F28: DOST ROs and Eligible Proponents | G28: 1835300
A29: 2023 | B29: 45078 | C29: APPROVAL | D29: ACU-N | E29: ACU-n's Marketing Campaign for DOST-TAPI's Technopreneurship Programs | F29: DOST ROs and Eligible Proponents | G29: 1500000
A30: 2023 | B30: 45139 | C30: APPROVAL | D30: ISTE | E30: International Ecotourism Travel Mart (IETM 2023) | F30: International School of Sustainable Tourism (ISST) | G30: 85000
